Workbook

Sheet PANEL
A1: Tara | B1: An | C1: Employment rate% | D1: Internet_Use % | E1: ICT_goods % | F1: HighManu % eports | G1: GDP_CAPITA $ | H1: GDP_annual growth % | I1: fixedborad per 100 subscribers | J1: R&D % of gdp | K1: youth employ % | L1: mobile_celular nr subs*100/pop | M1: unemploy by ead %
A2: Austria | B2: 2007 | C2: {=TRANSPOSE(EMPLOYrate!D11:S11)} -> 56.893 | D2: 69.37 | E2: {=TRANSPOSE(ictgoods!D2:S2)} -> 4.67 | F2: {=TRANSPOSE(hightechmanu!C2:R2)} -> 12.984024 | G2: {=TRANSPOSE(gdppercapita!D2:S2)} -> 46622.962 | H2: {=TRANSPOSE(gdpannual!D7:S7)} -> 3.7752247 | I2: {=TRANSPOSE(fixedbroadband!D13:S13)} -> 19.5493 | J2: {=TRANSPOSE(rdexpediture!D19:S19)} -> 2.41843 | K2: {=TRANSPOSE(YOUTH_EMPLOY!D2:S2)} -> 9.596 | L2: {=TRANSPOSE(mobile_celular!D19:S19)} -> 119.466 | M2: {=TRANSPOSE(unemployEAD!C2:R2)} -> 4.147
A3: Austria | B3: 2008 | C3: 57.558 | D3: 72.87 | E3: 4.34 | F3: 12.661119 | G3: 51581.398 | H3: 1.4533056 | I3: 20.7731 | J3: 2.56945 | K3: 8.72 | L3: 129.949 | M3: 3.615
A4: Austria | B4: 2009 | C4: 57.107 | D4: 73.45 | E4: 4.01 | F4: 13.437916 | G4: 47857.445 | H4: -3.5862647 | I4: 22.5106 | J4: 2.59674 | K4: 10.896 | L4: 137.015 | M4: 4.701
A5: Austria | B5: 2010 | C5: 57.343 | D5: 75.17 | E5: 3.95 | F5: 13.705374 | G5: 46611.139 | H5: 1.8089824 | I5: 24.5114 | J5: 2.7261 | K5: 9.673 | L5: 146.334 | M5: 4.411
A6: Austria | B6: 2011 | C6: 57.558 | D6: 78.74 | E6: 3.79 | F6: 13.255424 | G6: 51116.895 | H6: 2.927468 | I6: 24.9926 | J6: 2.66868 | K6: 9.173 | L6: 155.155 | M6: 4.016
A7: Austria | B7: 2012 | C7: 57.67 | D7: 80.03 | E7: 3.89 | F7: 14.544679 | G7: 48250.406 | H7: 0.62824624 | I7: 25.2645 | J7: 2.91472 | K7: 9.561 | L7: 161.156 | M7: 4.436
A8: Austria | B8: 2013 | C8: 57.538 | D8: 80.6188 | E8: 4.21 | F8: 15.369065 | G8: 50305.355 | H8: -0.25072642 | I8: 26.3223 | J8: 2.95492 | K8: 9.767 | L8: 156.483 | M8: 4.748
A9: Austria | B9: 2014 | C9: 57.16 | D9: 80.9958 | E9: 4.28 | F9: 15.490449 | G9: 51314.972 | H9: 0.75579885 | I9: 27.5977 | J9: 3.08429 | K9: 10.508 | L9: 151.531 | M9: 5.072
A10: Austria | B10: 2015 | C10: 57.115 | D10: 83.9401 | E10: 4.12 | F10: 15.032732 | G10: 43915.228 | H10: 1.3035233 | I10: 28.4069 | J10: 3.04969 | K10: 10.91 | L10: 155.837 | M10: 5.508
A11: Austria | B11: 2016 | C11: 57.427 | D11: 84.3237 | E11: 3.79 | F11: 14.453259 | G11: 45061.499 | H11: 2.1172196 | I11: 28.8776 | J11: 3.11655 | K11: 11.424 | L11: 126.798 | M11: 5.822
A12: Austria | B12: 2017 | C12: 57.703 | D12: 87.9356 | E12: 3.48 | F12: 12.8852 | G12: 47163.743 | H12: 2.2722499 | I12: 28.5426 | J12: 3.05656 | K12: 9.971 | L12: 123.415 | M12: 5.105
A13: Austria | B13: 2018 | C13: 58.298 | D13: 87.4791 | E13: 3.41 | F13: 11.650076 | G13: 51194.075 | H13: 2.4842211 | I13: 28.515 | J13: 3.09182 | K13: 9.572 | L13: 124.23 | M13: 4.311
A14: Austria | B14: 2019 | C14: 58.514 | D14: 87.7522 | E14: 3.13 | F14: 11.482535 | G14: 49885.995 | H14: 1.7549762 | I14: 28.3632 | J14: 3.13265 | K14: 8.767 | L14: 120.776 | M14: 3.997
... A17: Austria | B17: 2022 | C17: 58.441 | D17: 93.6141 | E17: 4.88 | F17: 14.91417 | G17: 52336.773 | H17: 5.3309638 | I17: 29.2343 | J17: 3.20048 | K17: 10.327 | L17: 121.166 | M17: 4.241
A18: Belgia | B18: 2007 | C18: {=TRANSPOSE(EMPLOYrate!D24:S24)} -> 49.589 | D18: 66.7604 | E18: {=TRANSPOSE(ictgoods!D25:S25)} -> 2.7 | F18: {=TRANSPOSE(hightechmanu!C3:R3)} -> 8.4658386 | G18: {=TRANSPOSE(gdppercapita!D3:S3)} -> 44319.165 | H18: {=TRANSPOSE(gdpannual!D15:S15)} -> 3.6769246 | I18: {=TRANSPOSE(fixedbroadband!D21:S21)} -> 25.6894 | J18: {=TRANSPOSE(rdexpediture!D21:S21)} -> 1.84999 | K18: {=TRANSPOSE(YOUTH_EMPLOY!D3:S3)} -> 18.841 | L18: {=TRANSPOSE(mobile_celular!D27:S27)} -> 101.06 | M18: {=TRANSPOSE(unemployEAD!C3:R3)} -> 7.592
A19: Belgia | B19: 2008 | C19: 49.934 | D19: 68.8573 | E19: 2.58 | F19: 8.9469498 | G19: 48303.398 | H19: 0.44690513 | I19: 27.8486 | J19: 1.93684 | K19: 17.97 | L19: 105.901 | M19: 6.94
A20: Belgia | B20: 2009 | C20: 49.244 | D20: 74.5441 | E20: 2.5 | F20: 11.357545 | G20: 44923.34 | H20: -1.9064411 | I20: 29.1619 | J20: 1.9986 | K20: 21.94 | L20: 108.9 | M20: 8.071
A21: Belgia | B21: 2010 | C21: 49.586 | D21: 77.6398 | E21: 2.03 | F21: 9.2652301 | G21: 44197.394 | H21: 2.7103115 | I21: 30.8426 | J21: 2.06188 | K21: 22.391 | L21: 111.132 | M21: 8.135
A22: Belgia | B22: 2011 | C22: 49.4 | D22: 81.61 | E22: 1.72 | F22: 8.6748384 | G22: 47760.83 | H22: 1.931155 | I22: 32.1032 | J22: 2.17332 | K22: 18.724 | L22: 113.202 | M22: 6.775
A23: Belgia | B23: 2012 | C23: 49.233 | D23: 80.72 | E23: 1.73 | F23: 8.9420008 | G23: 44874.171 | H23: 0.21580361 | I23: 33.2388 | J23: 2.28114 | K23: 19.738 | L23: 110.856 | M23: 7.751
A24: Belgia | B24: 2013 | C24: 49.047 | D24: 82.1702 | E24: 1.69 | F24: 10.640612 | G24: 46964.595 | H24: 0.30549455 | I24: 34.3085 | J24: 2.33073 | K24: 23.689 | L24: 110.349 | M24: 8.214
A25: Belgia | B25: 2014 | C25: 48.946 | D25: 85.0012 | E25: 1.74 | F25: 11.939352 | G25: 47995.779 | H25: 1.7655404 | I25: 35.782 | J25: 2.37002 | K25: 23.225 | L25: 113.6 | M25: 8.794
A26: Belgia | B26: 2015 | C26: 48.788 | D26: 85.0529 | E26: 2.18 | F26: 12.335174 | G26: 40893.805 | H26: 1.4741643 | I26: 36.5492 | J26: 2.42817 | K26: 22.125 | L26: 113.292 | M26: 8.699
A27: Belgia | B27: 2016 | C27: 48.952 | D27: 86.5165 | E27: 2.02 | F27: 13.331245 | G27: 41854.55 | H27: 1.1935027 | I27: 37.6813 | J27: 2.52338 | K27: 20.108 | L27: 110.749 | M27: 8.045
A28: Belgia | B28: 2017 | C28: 50.021 | D28: 87.6797 | E28: 1.95 | F28: 11.49179 | G28: 44035.324 | H28: 1.4744676 | I28: 38.4911 | J28: 2.66666 | K28: 19.236 | L28: 99.8304 | M28: 7.113
A29: Belgia | B29: 2018 | C29: 50.965 | D29: 88.6473 | E29: 1.77 | F29: 11.705864 | G29: 47487.21 | H29: 1.8779685 | I29: 39.4007 | J29: 2.86018 | K29: 15.748 | L29: 100.164 | M29: 5.951
A30: Belgia | B30: 2019 | C30: 51.475 | D30: 90.2754 | E30: 2.17 | F30: 14.144014 | G30: 46716.623 | H30: 2.44289 | I30: 39.9518 | J30: 3.1566 | K30: 14.236 | L30: 100.165 | M30: 5.302
... A33: Belgia | B33: 2022 | C33: 52.026 | D33: 94.0078 | E33: 1.64 | F33: 22.817914 | G33: 50605.75 | H33: 3.956238 | I33: 43.5657 | J33: 3.40544 | K33: 16.41 | L33: 101.68 | M33: 6.32
A34: Bulgaria | B34: 2007 | C34: {=TRANSPOSE(EMPLOYrate!D23:S23)} -> 48.979 | D34: 33.64 | E34: {=TRANSPOSE(ictgoods!D5:S5)} -> 1.92 | F34: {=TRANSPOSE(hightechmanu!C4:R4)} -> 6.2935056 | G34: {=TRANSPOSE(gdppercapita!D4:S4)} -> 5888.5708 | H34: {=TRANSPOSE(gdpannual!D5:S5)} -> 6.6543879 | I34: {=TRANSPOSE(fixedbroadband!D26:S26)} -> 8.29162 | J34: {=TRANSPOSE(rdexpediture!D3:S3)} -> 0.43003 | K34: {=TRANSPOSE(YOUTH_EMPLOY!D4:S4)} -> 15.183 | L34: {=TRANSPOSE(mobile_celular!D17:S17)} -> 130.455 | M34: {=TRANSPOSE(unemployEAD!C4:R4)} -> 5.761
A35: Bulgaria | B35: 2008 | C35: 50.79 | D35: 39.67 | E35: 2.17 | F35: 6.9730376 | G35: 7271.3034 | H35: 6.1295584 | I35: 11.1942 | J35: 0.44731 | K35: 12.804 | L35: 138.397 | M35: 4.514
A36: Bulgaria | B36: 2009 | C36: 49.407 | D36: 45 | E36: 3.02 | F36: 8.6660333 | G36: 6988.2732 | H36: -3.3471415 | I36: 13.3284 | J36: 0.49338 | K36: 16.263 | L36: 139.621 | M36: 6.159
A37: Bulgaria | B37: 2010 | C37: 47.905 | D37: 46.23 | E37: 2.47 | F37: 8.4042516 | G37: 6853.9481 | H37: 1.5553598 | I37: 15.1221 | J37: 0.56299 | K37: 21.95 | L37: 137.14 | M37: 9.692
A38: Bulgaria | B38: 2011 | C38: 46.599 | D38: 47.98 | E38: 2.13 | F38: 7.8156879 | G38: 7849.5806 | H38: 2.0901751 | I38: 17.0297 | J38: 0.5295 | K38: 25.056 | L38: 141.938 | M38: 10.462
A39: Bulgaria | B39: 2012 | C39: 46.566 | D39: 51.9 | E39: 1.96 | F39: 8.0475539 | G39: 7431.9579 | H39: 0.74881541 | I39: 18.2007 | J39: 0.60039 | K39: 28.11 | L39: 147.338 | M39: 11.667
A40: Bulgaria | B40: 2013 | C40: 46.925 | D40: 53.0615 | E40: 2.35 | F40: 8.2944022 | G40: 7795.9809 | H40: -0.54275139 | I40: 19.5682 | J40: 0.63424 | K40: 28.374 | L40: 144.355 | M40: 12.33
A41: Bulgaria | B41: 2014 | C41: 47.958 | D41: 55.4904 | E41: 2.52 | F41: 7.5780009 | G41: 8069.6001 | H41: 0.94944909 | I41: 20.5011 | J41: 0.79007 | K41: 23.774 | L41: 131.335 | M41: 10.647
A42: Bulgaria | B42: 2015 | C42: 49.124 | D42: 56.6563 | E42: 2.9 | F42: 8.4502667 | G42: 7268.6545 | H42: 3.3975534 | I42: 22.4944 | J42: 0.94947 | K42: 21.653 | L42: 128.103 | M42: 8.326
A43: Bulgaria | B43: 2016 | C43: 49.292 | D43: 59.8255 | E43: 2.85 | F43: 8.9861031 | G43: 7822.4992 | H43: 3.0266284 | I43: 23.8177 | J43: 0.77009 | K43: 17.224 | L43: 125.906 | M43: 6.718
A44: Bulgaria | B44: 2017 | C44: 51.942 | D44: 63.4101 | E44: 2.75 | F44: 9.6360885 | G44: 8696.6893 | H44: 2.7459268 | I44: 25.3925 | J44: 0.74037 | K44: 12.927 | L44: 120.596 | M44: 5.26
...

Sheet info 
A1: LINK
A3: https://data360.worldbank.org/en/indicator/WB_WDI_TX_VAL_ICTG_ZS_UN | B3: ict goods % of total goods exports
A5: https://data360.worldbank.org/en/indicator/WB_WDI_IT_NET_BBND_P2 | B5: fixed broadband subscriptions per 100 people
A7: https://data360.worldbank.org/en/indicator/ITU_DH_INT_USER_PT | B7: individuals using the internet %
A9: https://data360.worldbank.org/en/indicator/WB_WDI_TX_VAL_TECH_MF_ZS | B9: high tech export % manufactured
A11: https://data360.worldbank.org/en/indicator/WB_WDI_NY_GDP_MKTP_KD_ZG | B11: gdp annual growth %
A13: https://data360.worldbank.org/en/indicator/WB_WDI_NY_GDP_PCAP_CD | B13: gdp per capita curent $
A15: https://data360.worldbank.org/en/indicator/WB_WDI_GB_XPD_RSDV_GD_ZS | B15: r&d expenditure % of gdp
A17: https://data360.worldbank.org/en/indicator/WB_WDI_SL_EMP_TOTL_SP_NE_ZS | B17: employment rate %
A19: https://data360.worldbank.org/en/indicator/WB_HCP_UNE_2EAP_MF_Y | B19: youth employ %
A21: https://data360.worldbank.org/en/indicator/WB_GS_SL_UEM_ELV_ZS | B21: unemploy ead %
A23: https://data360.worldbank.org/en/indicator/WB_WDI_IT_CEL_SETS_P2 | B23: mobile celullar: number of subscriptions*100/population

Sheet ictgoods
A1: tara | D1: 2007 | E1: 2008 | F1: 2009 | G1: 2010 | H1: 2011 | I1: 2012 | J1: 2013 | K1: 2014 | L1: 2015 | M1: 2016 | N1: 2017 | O1: 2018 | P1: 2019 | Q1: 2020 | R1: 2021 | S1: 2022
A2: Austria | B2: ICT goods exports (% of total goods exports) | C2: Percentage | D2: 4.67 | E2: 4.34 | F2: 4.01 | G2: 3.95 | H2: 3.79 | I2: 3.89 | J2: 4.21 | K2: 4.28 | L2: 4.12 | M2: 3.79 | N2: 3.48 | O2: 3.41 | P2: 3.13 | Q2: 3.09 | R2: 4.95 | S2: 4.88
A3: Cyprus | B3: ICT goods exports (% of total goods exports) | C3: Percentage | D3: 6.21 | E3: 6.81 | F3: 8.98 | G3: 9.17 | H3: 5.64 | I3: 3.48 | J3: 3.88 | K3: 2.93 | L3: 3.56 | M3: 4.8 | N3: 4.91 | O3: 4.47 | P3: 2.3 | Q3: 1.91 | R3: 2.1 | S3: 1.66
A4: Finland | B4: ICT goods exports (% of total goods exports) | C4: Percentage | D4: 15.58 | E4: 14.88 | F4: 10.73 | G4: 6.36 | H4: 4.92 | I4: 3.98 | J4: 2.31 | K4: 2.62 | L4: 2.46 | M4: 2.69 | N4: 2.69 | O4: 2.6 | P4: 2.58 | Q4: 2.5 | R4: 2.56 | S4: 2.6
A5: Bulgaria | B5: ICT goods exports (% of total goods exports) | C5: Percentage | D5: 1.92 | E5: 2.17 | F5: 3.02 | G5: 2.47 | H5: 2.13 | I5: 1.96 | J5: 2.35 | K5: 2.52 | L5: 2.9 | M5: 2.85 | N5: 2.75 | O5: 3.25 | P5: 3.21 | Q5: 3.42 | R5: 3.29 | S5: 3.31
A6: Spain | B6: ICT goods exports (% of total goods exports) | C6: Percentage | D6: 2.64 | E6: 2.44 | F6: 2.19 | G6: 2.2 | H6: 1.61 | I6: 1.27 | J6: 1.07 | K6: 1.14 | L6: 1.25 | M6: 1.37 | N6: 1.52 | O6: 1.45 | P6: 1.63 | Q6: 1.72 | R6: 1.59 | S6: 1.37
A7: Italy | B7: ICT goods exports (% of total goods exports) | C7: Percentage | D7: 2.23 | E7: 1.94 | F7: 2.02 | G7: 2.15 | H7: 2.1 | I7: 1.86 | J7: 1.75 | K7: 1.67 | L7: 1.9 | M7: 1.86 | N7: 1.89 | O7: 1.99 | P7: 1.97 | Q7: 2.2 | R7: 2.01 | S7: 1.99
A8: Portugal | B8: ICT goods exports (% of total goods exports) | C8: Percentage | D8: 7.84 | E8: 6.93 | F8: 4.41 | G8: 4.01 | H8: 3.91 | I8: 3.44 | J8: 2.72 | K8: 2.29 | L8: 2.45 | M8: 3.32 | N8: 3.22 | O8: 3.03 | P8: 3.4 | Q8: 3.7 | R8: 3.51 | S8: 3.28
A9: Lithuania | B9: ICT goods exports (% of total goods exports) | C9: Percentage | D9: 3.88 | E9: 3.02 | F9: 2.49 | G9: 2.71 | H9: 2.4 | I9: 2.27 | J9: 2.43 | K9: 2.94 | L9: 3.95 | M9: 3.86 | N9: 4.08 | O9: 3.48 | P9: 3.44 | Q9: 3.92 | R9: 3.43 | S9: 3.2
A10: Croatia | B10: ICT goods exports (% of total goods exports) | C10: Percentage | D10: 2.83 | E10: 2.69 | F10: 2.6 | G10: 2.1 | H10: 1.55 | I10: 1.89 | J10: 2.55 | K10: 2.01 | L10: 2.45 | M10: 2.7 | N10: 2.52 | O10: 2.33 | P10: 2.33 | Q10: 2.46 | R10: 2.14 | S10: 1.6
A11: Hungary | B11: ICT goods exports (% of total goods exports) | C11: Percentage | D11: 22.52 | E11: 22.66 | F11: 26 | G11: 25.59 | H11: 21.58 | I11: 17.45 | J11: 14.77 | K11: 11.92 | L11: 11.62 | M11: 11.38 | N11: 11.42 | O11: 11.34 | P11: 12.82 | Q11: 13.09 | R11: 12.29 | S11: 10.33
A12: Greece | B12: ICT goods exports (% of total goods exports) | C12: Percentage | D12: 2.39 | E12: 2.21 | F12: 2.09 | G12: 1.99 | H12: 1.97 | I12: 1.65 | J12: 1.36 | K12: 2.41 | L12: 3.07 | M12: 3.49 | N12: 2.78 | O12: 3.11 | P12: 3.11 | Q12: 3.51 | R12: 3.04 | S12: 2.82
A13: France | B13: ICT goods exports (% of total goods exports) | C13: Percentage | D13: 4.84 | E13: 4.26 | F13: 4.26 | G13: 4.41 | H13: 4.23 | I13: 4.07 | J13: 3.96 | K13: 3.86 | L13: 4.02 | M13: 3.98 | N13: 3.93 | O13: 3.96 | P13: 3.79 | Q13: 3.77 | R13: 3.64 | S13: 3.65
... A28: Malta | B28: ICT goods exports (% of total goods exports) | C28: Percentage | D28: 46.22 | E28: 43.19 | F28: 42.31 | G28: 30.87 | H28: 22.89 | I28: 20.2 | J28: 18.8 | K28: 15.17 | L28: 14.9 | M28: 13.22 | N28: 13.3 | O28: 15.69 | P28: 13.59 | Q28: 19.66 | R28: 16.16 | S28: 25.7

Sheet ictuse
A1: tara | D1: 2007 | E1: 2008 | F1: 2009 | G1: 2010 | H1: 2011 | I1: 2012 | J1: 2013 | K1: 2014 | L1: 2015 | M1: 2016 | N1: 2017 | O1: 2018 | P1: 2019 | Q1: 2020 | R1: 2021 | S1: 2022
A2: Austria | B2: ITU_DH_INT_USER_PT | C2: Percentage of individuals using the internet (ITU) | D2: 69.37 | E2: 72.87 | F2: 73.45 | G2: 75.17 | H2: 78.74 | I2: 80.03 | J2: 80.6188 | K2: 80.9958 | L2: 83.9401 | M2: 84.3237 | N2: 87.9356 | O2: 87.4791 | P2: 87.7522 | Q2: 87.5294 | R2: 92.5292 | S2: 93.6141
A3: Belgium | B3: ITU_DH_INT_USER_PT | C3: Percentage of individuals using the internet (ITU) | D3: 66.7604 | E3: 68.8573 | F3: 74.5441 | G3: 77.6398 | H3: 81.61 | I3: 80.72 | J3: 82.1702 | K3: 85.0012 | L3: 85.0529 | M3: 86.5165 | N3: 87.6797 | O3: 88.6473 | P3: 90.2754 | Q3: 91.5264 | R3: 92.7887 | S3: 94.0078
A4: Bulgaria | B4: ITU_DH_INT_USER_PT | C4: Percentage of individuals using the internet (ITU) | D4: 33.64 | E4: 39.67 | F4: 45 | G4: 46.23 | H4: 47.98 | I4: 51.9 | J4: 53.0615 | K4: 55.4904 | L4: 56.6563 | M4: 59.8255 | N4: 63.4101 | O4: 64.782 | P4: 67.947 | Q4: 70.1625 | R4: 75.2714 | S4: 79.1269
A5: Czechia | B5: ITU_DH_INT_USER_PT | C5: Percentage of individuals using the internet (ITU) | D5: 51.93 | E5: 62.97 | F5: 64.43 | G5: 68.82 | H5: 70.49 | I5: 73.43 | J5: 74.1104 | K5: 74.2317 | L5: 75.6688 | M5: 76.4812 | N5: 78.7192 | O5: 80.6882 | P5: 80.8669 | Q5: 81.3389 | R5: 82.6706 | S5: 84.5401
A6: Germany | B6: ITU_DH_INT_USER_PT | C6: Percentage of individuals using the internet (ITU) | D6: 75.16 | E6: 78 | F6: 79 | G6: 82 | H6: 81.27 | I6: 82.35 | J6: 84.17 | K6: 86.1937 | L6: 87.5898 | M6: 84.1652 | N6: 84.3942 | O6: 87.0371 | P6: 88.1345 | Q6: 89.8129 | R6: 91.4306 | S6: 91.6298
A7: Denmark | B7: ITU_DH_INT_USER_PT | C7: Percentage of individuals using the internet (ITU) | D7: 85.03 | E7: 85.02 | F7: 86.84 | G7: 88.72 | H7: 89.81 | I7: 92.26 | J7: 94.6297 | K7: 95.9935 | L7: 96.3305 | M7: 96.9678 | N7: 97.0994 | O7: 97.3192 | P7: 98.0464 | Q7: 96.5491 | R7: 98.8659 | S7: 97.8601
A8: Spain | B8: ITU_DH_INT_USER_PT | C8: Percentage of individuals using the internet (ITU) | D8: 55.11 | E8: 59.6 | F8: 62.4 | G8: 65.8 | H8: 67.09 | I8: 69.81 | J8: 71.635 | K8: 76.1867 | L8: 78.6896 | M8: 80.5613 | N8: 84.6022 | O8: 86.1072 | P8: 90.7187 | Q8: 93.2056 | R8: 93.8975 | S8: 94.4855
A9: Estonia | B9: ITU_DH_INT_USER_PT | C9: Percentage of individuals using the internet (ITU) | D9: 66.19 | E9: 70.58 | F9: 72.5 | G9: 74.1 | H9: 76.5 | I9: 78.3899 | J9: 80.0043 | K9: 84.2415 | L9: 88.4097 | M9: 87.2402 | N9: 88.1025 | O9: 89.357 | P9: 90.2289 | Q9: 89.0583 | R9: 90.9797 | S9: 91.5202
A10: Finland | B10: ITU_DH_INT_USER_PT | C10: Percentage of individuals using the internet (ITU) | D10: 80.78 | E10: 83.67 | F10: 82.49 | G10: 86.89 | H10: 88.71 | I10: 89.88 | J10: 91.5144 | K10: 86.5304 | L10: 86.4221 | M10: 87.7036 | N10: 87.4689 | O10: 88.89 | P10: 89.6074 | Q10: 92.1703 | R10: 92.8081 | S10: 92.9888
A11: France | B11: ITU_DH_INT_USER_PT | C11: Percentage of individuals using the internet (ITU) | D11: 66.09 | E11: 70.68 | F11: 71.58 | G11: 77.28 | H11: 77.82 | I11: 81.44 | J11: 81.9198 | K11: 83.7511 | L11: 78.006 | M11: 79.2698 | N11: 80.5025 | O11: 82.0432 | P11: 83.3397 | Q11: 84.7064 | R11: 86.0955 | S11: 85.3333
A12: Greece | B12: ITU_DH_INT_USER_PT | C12: Percentage of individuals using the internet (ITU) | D12: 35.88 | E12: 38.2 | F12: 42.4 | G12: 44.4 | H12: 51.65 | I12: 55.07 | J12: 59.8663 | K12: 63.2073 | L12: 66.835 | M12: 69.0879 | N12: 69.893 | O12: 72.2384 | P12: 75.6712 | Q12: 78.1158 | R12: 78.4943 | S12: 83.1707
A13: Croatia | B13: ITU_DH_INT_USER_PT | C13: Percentage of individuals using the internet (ITU) | D13: 41.44 | E13: 44.24 | F13: 50.58 | G13: 56.55 | H13: 57.79 | I13: 61.94 | J13: 66.7476 | K13: 68.5679 | L13: 69.845 | M13: 72.6973 | N13: 67.0962 | O13: 75.2946 | P13: 79.0798 | Q13: 78.3209 | R13: 81.254 | S13: 82.0716
... A28: Netherlands | B28: ITU_DH_INT_USER_PT | C28: Percentage of individuals using the internet (ITU) | D28: 85.82 | E28: 87.42 | F28: 89.63 | G28: 90.72 | H28: 91.42 | I28: 92.86 | J28: 93.9564 | K28: 91.6667 | L28: 91.7241 | M28: 90.411 | N28: 93.1973 | O28: 91.8919 | P28: 93.2886 | Q28: 91.3333 | R28: 92.053 | S28: 92.5197
D35: {=TRANSPOSE(D10:S10)} -> 80.78
D36: 83.67
D37: 82.49
D38: 86.89
D39: 88.71
D40: 89.88
D41: 91.5144
D42: 86.5304
D43: 86.4221
D44: 87.7036
D45: 87.4689
D46: 88.89
D47: 89.6074
... D50: 92.9888

Sheet mobile_celular
A1: REF_AREA_LABEL | B1: INDICATOR_LABEL | C1: UNIT_MEASURE_LABEL | D1: 2007 | E1: 2008 | F1: 2009 | G1: 2010 | H1: 2011 | I1: 2012 | J1: 2013 | K1: 2014 | L1: 2015 | M1: 2016 | N1: 2017 | O1: 2018 | P1: 2019 | Q1: 2020 | R1: 2021 | S1: 2022
A2: Cyprus | B2: Mobile cellular subscriptions (per 100 people) | C2: Per 100 persons | D2: 127.294 | E2: 127.587 | F2: 119.341 | G2: 123.133 | H2: 126.56 | I2: 128.298 | J2: 128.161 | K2: 131.145 | L2: 130.982 | M2: 132.637 | N2: 136.172 | O2: 137.045 | P2: 139.994 | Q2: 138.388 | R2: 145.992 | S2: 151.241
A3: Slovenia | B3: Mobile cellular subscriptions (per 100 people) | C3: Per 100 persons | D3: 95.7428 | E3: 101.472 | F3: 103.185 | G3: 103.783 | H3: 105.845 | I3: 109.148 | J3: 111.045 | K3: 113.019 | L3: 114.271 | M3: 115.736 | N3: 118.462 | O3: 119.153 | P3: 120.569 | Q3: 121.331 | R3: 123.363 | S3: 126.459
A4: Luxembourg | B4: Mobile cellular subscriptions (per 100 people) | C4: Per 100 persons | D4: 142.524 | E4: 144.584 | F4: 144.524 | G4: 143.277 | H4: 147.512 | I4: 143.388 | J4: 145.093 | K4: 144.244 | L4: 141.659 | M4: 130.933 | N4: 133.111 | O4: 131.327 | P4: 131.87 | Q4: 132.909 | R4: 136.871 | S4: 139.651
A5: Croatia | B5: Mobile cellular subscriptions (per 100 people) | C5: Per 100 persons | D5: 116.651 | E5: 105.566 | F5: 108.456 | G5: 114.582 | H5: 119.49 | I5: 116.719 | J5: 111.282 | K5: 105.732 | L5: 105.544 | M5: 106.718 | N5: 105.795 | O5: 109.034 | P5: 110.494 | Q5: 110.666 | R5: 112.169 | S5: 114.677
A6: Italy | B6: Mobile cellular subscriptions (per 100 people) | C6: Per 100 persons | D6: 151.925 | E6: 151.676 | F6: 150.295 | G6: 155.684 | H6: 159.093 | I6: 160.559 | J6: 159.698 | K6: 148.217 | L6: 144.764 | M6: 142.127 | N6: 138.882 | O6: 138.265 | P6: 132.181 | Q6: 129.49 | R6: 130.781 | S6: 131.674
A7: Malta | B7: Mobile cellular subscriptions (per 100 people) | C7: Per 100 persons | D7: 88.3348 | E7: 92.044 | F7: 100.306 | G7: 107.791 | H7: 122.872 | I7: 124.757 | J7: 129.922 | K7: 125.719 | L7: 117.794 | M7: 128.599 | N7: 129.249 | O7: 127.094 | P7: 125.866 | Q7: 122.176 | R7: 123.941 | S7: 132.861
A8: Denmark | B8: Mobile cellular subscriptions (per 100 people) | C8: Per 100 persons | D8: 115.497 | E8: 119.353 | F8: 123.727 | G8: 115.734 | H8: 128.763 | I8: 130.416 | J8: 125.213 | K8: 126.869 | L8: 124.554 | M8: 121.941 | N8: 123.862 | O8: 124.55 | P8: 124.573 | Q8: 124.37 | R8: 125.604 | S8: 126.484
A9: Hungary | B9: Mobile cellular subscriptions (per 100 people) | C9: Per 100 persons | D9: 109.925 | E9: 122.038 | F9: 117.909 | G9: 120.369 | H9: 117.526 | I9: 116.768 | J9: 117.2 | K9: 118.896 | L9: 100.624 | M9: 101.442 | N9: 101.629 | O9: 102.737 | P9: 105.142 | Q9: 105.982 | R9: 105.137 | S9: 105.794
A10: Finland | B10: Mobile cellular subscriptions (per 100 people) | C10: Per 100 persons | D10: 114.962 | E10: 128.543 | F10: 144.226 | G10: 156.432 | H10: 165.917 | I10: 172.147 | J10: 136.259 | K10: 139.199 | L10: 134.974 | M10: 131.383 | N10: 129.983 | O10: 129.629 | P10: 129.488 | Q10: 128.761 | R10: 129.036 | S10: 128.023
A11: Lithuania | B11: Mobile cellular subscriptions (per 100 people) | C11: Per 100 persons | D11: 152.012 | E11: 157.032 | F11: 156.848 | G11: 157.89 | H11: 163.043 | I11: 167.226 | J11: 154.341 | K11: 145.494 | L11: 143.991 | M11: 146.55 | N11: 154.148 | O11: 134.334 | P11: 132.529 | Q11: 131.341 | R11: 133.357 | S11: 135.834
A12: Poland | B12: Mobile cellular subscriptions (per 100 people) | C12: Per 100 persons | D12: 108.859 | E12: 115.608 | F12: 117.906 | G12: 123.249 | H12: 131.28 | I12: 141.41 | J12: 148.912 | K12: 148.713 | L12: 142.52 | M12: 138.519 | N12: 131.901 | O12: 126.266 | P12: 126.597 | Q12: 129.288 | R12: 132.987 | S12: 137.002
... A28: Czechia | B28: Mobile cellular subscriptions (per 100 people) | C28: Per 100 persons | D28: 127.967 | E28: 132.779 | F28: 125.349 | G28: 123.605 | H28: 125.46 | I28: 128.69 | J28: 130.521 | K28: 132.289 | L28: 118.34 | M28: 118.544 | N28: 119.874 | O28: 120.432 | P28: 124.126 | Q28: 123.219 | R28: 126.173 | S28: 128.105

Sheet unemployEAD
A1: tara | B1: UNIT | C1: 2007 | D1: 2008 | E1: 2009 | F1: 2010 | G1: 2011 | H1: 2012 | I1: 2013 | J1: 2014 | K1: 2015 | L1: 2016 | M1: 2017 | N1: 2018 | O1: 2019 | P1: 2020 | Q1: 2021 | R1: 2022
A2: Austria | B2: Unemployment by level of education (%) | C2: 4.147 | D2: 3.615 | E2: 4.701 | F2: 4.411 | G2: 4.016 | H2: 4.436 | I2: 4.748 | J2: 5.072 | K2: 5.508 | L2: 5.822 | M2: 5.105 | N2: 4.311 | O2: 3.997 | P2: 4.885 | Q2: 6.045 | R2: 4.241
A3: Belgium | B3: Unemployment by level of education (%) | C3: 7.592 | D3: 6.94 | E3: 8.071 | F3: 8.135 | G3: 6.775 | H3: 7.751 | I3: 8.214 | J3: 8.794 | K3: 8.699 | L3: 8.045 | M3: 7.113 | N3: 5.951 | O3: 5.302 | P3: 5.732 | Q3: 6.972 | R3: 6.32
A4: Bulgaria | B4: Unemployment by level of education (%) | C4: 5.761 | D4: 4.514 | E4: 6.159 | F4: 9.692 | G4: 10.462 | H4: 11.667 | I4: 12.33 | J4: 10.647 | K4: 8.326 | L4: 6.718 | M4: 5.26 | N4: 4.506 | O4: 3.388 | P4: 4.707 | Q4: 4.915 | R4: 4.024
A5: Cyprus | B5: Unemployment by level of education (%) | C5: 3.915 | D5: 3.729 | E5: 5.84 | F5: 6.449 | G5: 8.878 | H5: 13.06 | I5: 17.434 | J5: 18.396 | K5: 16.676 | L5: 14.321 | M5: 11.467 | N5: 8.997 | O5: 8.057 | P5: 8.692 | Q5: 8.81 | R5: 7.784
A6: Czechia | B6: Unemployment by level of education (%) | C6: 4.713 | D6: 3.673 | E6: 6.143 | F6: 6.971 | G6: 6.446 | H6: 6.585 | I6: 6.929 | J6: 6.018 | K6: 4.702 | L6: 3.498 | M6: 2.691 | N6: 2.059 | O6: 1.749 | P6: 2.394 | Q6: 2.686 | R6: 2.038
A7: Germany | B7: Unemployment by level of education (%) | C7: 8.249 | D7: 7.222 | E7: 7.599 | F7: 6.83 | G7: 5.703 | H7: 5.229 | I7: 5.085 | J7: 4.632 | K7: 4.238 | L7: 3.689 | M7: 3.294 | N7: 2.881 | O7: 2.71 | P7: 3.238 | Q7: 3.141 | R7: 2.711
A8: Denmark | B8: Unemployment by level of education (%) | C8: 2.996 | D8: 2.96 | E8: 5.91 | F8: 7.073 | G8: 6.786 | H8: 6.905 | I8: 6.551 | J8: 6.134 | K8: 5.38 | L8: 5.134 | M8: 4.681 | N8: 4.08 | O8: 4.119 | P8: 4.775 | Q8: 4.46 | R8: 3.739
A9: Spain | B9: Unemployment by level of education (%) | C9: 8.14 | D9: 10.449 | E9: 16.832 | F9: 18.973 | G9: 21.166 | H9: 24.104 | I9: 25.852 | J9: 24.158 | K9: 21.576 | L9: 19.164 | M9: 16.974 | N9: 15.477 | O9: 14.489 | P9: 16.505 | Q9: 16.063 | R9: 14.064
A10: Estonia | B10: Unemployment by level of education (%) | C10: 10.93 | D10: 11.964 | E10: 27.775 | F10: 30.005 | G10: 25.486 | H10: 22.863 | I10: 14.572 | J10: 12.79 | K10: 12.286 | L10: 12.887 | M10: 10.769 | N10: 10.536 | O10: 9.644 | P10: 13.567 | Q10: 14.234 | R10: 12.007
A11: Finland | B11: Unemployment by level of education (%) | C11: 7.041 | D11: 6.383 | E11: 9.146 | F11: 8.925 | G11: 8.178 | H11: 8.201 | I11: 8.756 | J11: 9.4 | K11: 10.243 | L11: 9.51 | M11: 9.422 | N11: 8.281 | O11: 7.197 | P11: 8.91 | Q11: 7.976 | R11: 7.118
A12: France | B12: Unemployment by level of education (%) | C12: 7.149 | D12: 6.911 | E12: 8.797 | F12: 8.741 | G12: 8.9 | H12: 9.842 | I12: 10.116 | J12: 10.624 | K12: 10.799 | L12: 10.663 | M12: 10.071 | N12: 9.654 | O12: 9.145 | P12: 8.854 | Q12: 8.481 | R12: 8.179
... A28: Sweden | B28: Unemployment by level of education (%) | C28: 5.367 | D28: 5.376 | E28: 8.019 | F28: 8.096 | G28: 7.05 | H28: 7.118 | I28: 7.133 | J28: 7.003 | K28: 6.223 | L28: 5.66 | M28: 5.118 | N28: 4.622 | O28: 5.014 | P28: 6.316 | Q28: 6.668 | R28: 5.655

Sheet rdexpediture
A1: REF_AREA_LABEL | B1: INDICATOR_LABEL | C1: UNIT_MEASURE_LABEL | D1: 2007 | E1: 2008 | F1: 2009 | G1: 2010 | H1: 2011 | I1: 2012 | J1: 2013 | K1: 2014 | L1: 2015 | M1: 2016 | N1: 2017 | O1: 2018 | P1: 2019 | Q1: 2020 | R1: 2021 | S1: 2022
A2: Portugal | B2: Research and development expenditure (% of GDP) | C2: Percentage of GDP | D2: 1.12417 | E2: 1.44335 | F2: 1.58001 | G2: 1.53529 | H2: 1.45741 | I2: 1.37861 | J2: 1.32468 | K2: 1.28992 | L2: 1.2433 | M2: 1.28075 | N2: 1.31928 | O2: 1.34955 | P2: 1.39562 | Q2: 1.61392 | R2: 1.67051 | S2: 1.70179
A3: Bulgaria | B3: Research and development expenditure (% of GDP) | C3: Percentage of GDP | D3: 0.43003 | E3: 0.44731 | F3: 0.49338 | G3: 0.56299 | H3: 0.5295 | I3: 0.60039 | J3: 0.63424 | K3: 0.79007 | L3: 0.94947 | M3: 0.77009 | N3: 0.74037 | O3: 0.75413 | P3: 0.83274 | Q3: 0.84967 | R3: 0.77278 | S3: 0.75421
A4: Slovak Republic | B4: Research and development expenditure (% of GDP) | C4: Percentage of GDP | D4: 0.44746 | E4: 0.46137 | F4: 0.47272 | G4: 0.6055 | H4: 0.65255 | I4: 0.79461 | J4: 0.82005 | K4: 0.877 | L4: 1.15727 | M4: 0.78857 | N4: 0.88456 | O4: 0.83555 | P4: 0.8224 | Q4: 0.89773 | R4: 0.91611 | S4: 0.97939
A5: Sweden | B5: Research and development expenditure (% of GDP) | C5: Percentage of GDP | D5: 3.23383 | E5: 3.46999 | F5: 3.39528 | G5: 3.16789 | H5: 3.18702 | I5: 3.23025 | J5: 3.26042 | K5: 3.10184 | L5: 3.21903 | M5: 3.24736 | N5: 3.36279 | O5: 3.32106 | P5: 3.38758 | Q5: 3.4896 | R5: 3.40216 | S5: 3.40822
A6: Romania | B6: Research and development expenditure (% of GDP) | C6: Percentage of GDP | D6: 0.51148 | E6: 0.55215 | F6: 0.44395 | G6: 0.44666 | H6: 0.47459 | I6: 0.4624 | J6: 0.39024 | K6: 0.38208 | L6: 0.48796 | M6: 0.48864 | N6: 0.50693 | O6: 0.49729 | P6: 0.47616 | Q6: 0.46538 | R6: 0.47234 | S6: 0.45881
A7: Netherlands | B7: Research and development expenditure (% of GDP) | C7: Percentage of GDP | D7: 1.6703 | E7: 1.62269 | F7: 1.6657 | G7: 1.70404 | H7: 1.88131 | I7: 1.91627 | J7: 2.15606 | K7: 2.1733 | L7: 2.14606 | M7: 2.15081 | N7: 2.17857 | O7: 2.1388 | P7: 2.18435 | Q7: 2.32182 | R7: 2.26877 | S7: 2.25533
A8: Italy | B8: Research and development expenditure (% of GDP) | C8: Percentage of GDP | D8: 1.12899 | E8: 1.15972 | F8: 1.21787 | G8: 1.21797 | H8: 1.20155 | I8: 1.26219 | J8: 1.30107 | K8: 1.3384 | L8: 1.3385 | M8: 1.36642 | N8: 1.37013 | O8: 1.42443 | P8: 1.46159 | Q8: 1.5066 | R8: 1.42658 | S8: 1.39014
A9: Finland | B9: Research and development expenditure (% of GDP) | C9: Percentage of GDP | D9: 3.33704 | E9: 3.53697 | F9: 3.73402 | G9: 3.70532 | H9: 3.61806 | I9: 3.39832 | J9: 3.27137 | K9: 3.14751 | L9: 2.87196 | M9: 2.72442 | N9: 2.72787 | O9: 2.75749 | P9: 2.79961 | Q9: 2.91243 | R9: 2.9885 | S9: 2.96469
A10: Germany | B10: Research and development expenditure (% of GDP) | C10: Percentage of GDP | D10: 2.46048 | E10: 2.61513 | F10: 2.74266 | G10: 2.73024 | H10: 2.80555 | I10: 2.88166 | J10: 2.83599 | K10: 2.87784 | L10: 2.93379 | M10: 2.94039 | N10: 3.0471 | O10: 3.11011 | P10: 3.16701 | Q10: 3.13136 | R10: 3.12882 | S10: 3.13236
A11: Cyprus | B11: Research and development expenditure (% of GDP) | C11: Percentage of GDP | D11: 0.40007 | E11: 0.38594 | F11: 0.44437 | G11: 0.44292 | H11: 0.45263 | I11: 0.43765 | J11: 0.48485 | K11: 0.51205 | L11: 0.47529 | M11: 0.5197 | N11: 0.54259 | O11: 0.61405 | P11: 0.70945 | Q11: 0.83654 | R11: 0.8003 | S11: 0.74527
A12: Czechia | B12: Research and development expenditure (% of GDP) | C12: Percentage of GDP | D12: 1.29572 | E12: 1.23358 | F12: 1.28656 | G12: 1.3267 | H12: 1.54477 | I12: 1.76967 | J12: 1.87924 | K12: 1.95833 | L12: 1.91689 | M12: 1.67003 | N12: 1.76855 | O12: 1.89906 | P12: 1.92734 | Q12: 1.98599 | R12: 1.99601 | S12: 1.9642
... A28: Luxembourg | B28: Research and development expenditure (% of GDP) | C28: Percentage of GDP | D28: 1.57165 | E28: 1.54663 | F28: 1.58839 | G28: 1.42373 | H28: 1.42453 | I28: 1.20664 | J28: 1.23381 | K28: 1.217 | L28: 1.25226 | M28: 1.2669 | N28: 1.23898 | O28: 1.1718 | P28: 1.18177 | Q28: 1.09584 | R28: 1.0412 | S28: 0.97653

Sheet YOUTH_EMPLOY
A1: REF_AREA_LABEL | B1: INDICATOR_LABEL | C1: SEX | D1: 2007 | E1: 2008 | F1: 2009 | G1: 2010 | H1: 2011 | I1: 2012 | J1: 2013 | K1: 2014 | L1: 2015 | M1: 2016 | N1: 2017 | O1: 2018 | P1: 2019 | Q1: 2020 | R1: 2021 | S1: 2022
A2: Austria | B2: Youth unemployment rate (%) | C2: _T | D2: 9.596 | E2: 8.72 | F2: 10.896 | G2: 9.673 | H2: 9.173 | I2: 9.561 | J2: 9.767 | K2: 10.508 | L2: 10.91 | M2: 11.424 | N2: 9.971 | O2: 9.572 | P2: 8.767 | Q2: 10.325 | R2: 12.023 | S2: 10.327
A3: Belgium | B3: Youth unemployment rate (%) | C3: _T | D3: 18.841 | E3: 17.97 | F3: 21.94 | G3: 22.391 | H3: 18.724 | I3: 19.738 | J3: 23.689 | K3: 23.225 | L3: 22.125 | M3: 20.108 | N3: 19.236 | O3: 15.748 | P3: 14.236 | Q3: 15.326 | R3: 18.206 | S3: 16.41
A4: Bulgaria | B4: Youth unemployment rate (%) | C4: _T | D4: 15.183 | E4: 12.804 | F4: 16.263 | G4: 21.95 | H4: 25.056 | I4: 28.11 | J4: 28.374 | K4: 23.774 | L4: 21.653 | M4: 17.224 | N4: 12.927 | O4: 12.676 | P4: 8.898 | Q4: 14.214 | R4: 15.823 | S4: 10.742
A5: Cyprus | B5: Youth unemployment rate (%) | C5: _T | D5: 9.486 | E5: 8.532 | F5: 13.276 | G5: 15.852 | H5: 21.156 | I5: 27.244 | J5: 38.083 | K5: 35.516 | L5: 32.539 | M5: 28.902 | N5: 25.013 | O5: 20.654 | P5: 16.856 | Q5: 18.491 | R5: 17.173 | S5: 18.707
A6: Czechia | B6: Youth unemployment rate (%) | C6: _T | D6: 10.734 | E6: 9.874 | F6: 16.656 | G6: 18.356 | H6: 18.077 | I6: 19.508 | J6: 18.958 | K6: 15.841 | L6: 12.582 | M6: 10.488 | N6: 7.936 | O6: 6.714 | P6: 5.615 | Q6: 7.936 | R6: 8.134 | S6: 6.72
A7: Germany | B7: Youth unemployment rate (%) | C7: _T | D7: 11.824 | E7: 10.929 | F7: 11.309 | G7: 10.416 | H7: 8.927 | I7: 8.119 | J7: 7.825 | K7: 7.612 | L7: 7.328 | M7: 7.079 | N7: 6.77 | O7: 6.22 | P7: 5.859 | Q7: 7.862 | R7: 6.665 | S7: 6.04
A8: Denmark | B8: Youth unemployment rate (%) | C8: _T | D8: 7.495 | E8: 9.471 | F8: 13.441 | G8: 15.554 | H8: 16.306 | I8: 15.775 | J8: 14.774 | K8: 14.196 | L8: 12.152 | M8: 12.147 | N8: 12.384 | O8: 10.52 | P8: 10.041 | Q8: 11.588 | R8: 10.808 | S8: 10.533
A9: Spain | B9: Youth unemployment rate (%) | C9: _T | D9: 18.087 | E9: 24.443 | F9: 37.71 | G9: 41.453 | H9: 46.158 | I9: 52.829 | J9: 55.444 | K9: 53.169 | L9: 48.353 | M9: 44.445 | N9: 38.594 | O9: 34.362 | P9: 32.555 | Q9: 38.312 | R9: 34.844 | S9: 29.852
A10: Estonia | B10: Youth unemployment rate (%) | C10: _T | D10: 10.097 | E10: 12.032 | F10: 27.41 | G10: 32.938 | H10: 22.386 | I10: 20.862 | J10: 18.704 | K10: 14.975 | L10: 14.342 | M10: 14.125 | N10: 12.175 | O10: 12.076 | P10: 11.623 | Q10: 18.417 | R10: 16.622 | S10: 18.392
A11: Finland | B11: Youth unemployment rate (%) | C11: _T | D11: 16.426 | E11: 16.337 | F11: 21.376 | G11: 21.288 | H11: 19.934 | I11: 18.868 | J11: 19.817 | K11: 20.454 | L11: 22.304 | M11: 20.057 | N11: 20.041 | O11: 16.958 | P11: 17.128 | Q11: 21.193 | R11: 17.058 | S11: 14.138
A12: France | B12: Youth unemployment rate (%) | C12: _T | D12: 19.644 | E12: 19.214 | F12: 24.006 | G12: 23.592 | H12: 23.018 | I12: 24.949 | J12: 24.363 | K12: 24.828 | L12: 25.262 | M12: 24.938 | N12: 22.572 | O12: 20.953 | P12: 19.929 | Q12: 20.398 | R12: 19.283 | S12: 17.851
... A27: Sweden | B27: Youth unemployment rate (%) | C27: _T | D27: 19.26 | E27: 20.206 | F27: 25.024 | G27: 24.761 | H27: 22.784 | I27: 23.609 | J27: 23.519 | K27: 22.822 | L27: 20.365 | M27: 18.896 | N27: 17.875 | O27: 17.4 | P27: 20.094 | Q27: 23.895 | R27: 24.599 | S27: 21.607
A28: Netherlands | D28: 9.102 | E28: 8.32 | F28: 9.876 | G28: 10.77 | H28: 9.78 | I28: 11.457 | J28: 12.943 | K28: 12.529 | L28: 11.103 | M28: 10.639 | N28: 8.715 | O28: 7.044 | P28: 6.604 | Q28: 8.875 | R28: 9.331 | S28: 7.643

Sheet employmentRATE
A1: REF_AREA_LABEL | B1: INDICATOR_LABEL | C1: UNIT_MEASURE_LABEL | D1: 2007 | E1: 2008 | F1: 2009 | G1: 2010 | H1: 2011 | I1: 2012 | J1: 2013 | K1: 2014 | L1: 2015 | M1: 2016 | N1: 2017 | O1: 2018 | P1: 2019 | Q1: 2020 | R1: 2021 | S1: 2022 | T1: 2023 | U1: 2024
A2: Malta | B2: Employment to population ratio, 15+, total (%) (national estimate) | C2: Percentage | D2: 46626 | E2: 47054 | F2: 49957 | G2: 50557 | H2: 51631 | I2: 53068 | J2: 54781 | K2: 56222 | L2: 56972 | M2: 58437 | N2: 59.99 | O2: 61831 | P2: 62883 | Q2: 63551 | R2: 65584 | S2: 68072 | T2: 69265 | U2: 65006
A3: Ireland | B3: Employment to population ratio, 15+, total (%) (national estimate) | C3: Percentage | D3: 63307 | E3: 61472 | F3: 56006 | G3: 53502 | H3: 52449 | I3: 52114 | J3: 53453 | K3: 54431 | L3: 55691 | M3: 56971 | N3: 57818 | O3: 58594 | P3: 59253 | Q3: 57684 | R3: 59629 | S3: 61792 | T3: 63699 | U3: 62992
A4: Cyprus | B4: Employment to population ratio, 15+, total (%) (national estimate) | C4: Percentage | D4: 61863 | E4: 61.86 | F4: 60308 | G4: 60246 | H4: 58729 | I4: 55946 | J4: 53252 | K4: 53493 | L4: 53004 | M4: 53327 | N4: 54822 | O4: 57174 | P4: 58507 | Q4: 57935 | R4: 59035 | S4: 60678 | T4: 61716 | U4: 61921
A5: Estonia | B5: Employment to population ratio, 15+, total (%) (national estimate) | C5: Percentage | D5: 57773 | E5: 57773 | F5: 52493 | G5: 50392 | H5: 53747 | I5: 55167 | J5: 56033 | K5: 56627 | L5: 58139 | M5: 58653 | N5: 59889 | O5: 60397 | P5: 60706 | Q5: 59098 | R5: 59753 | S5: 61987 | T5: 62219 | U5: 61953
A6: Portugal | B6: Employment to population ratio, 15+, total (%) (national estimate) | C6: Percentage | D6: 57.25 | E6: 57344 | F6: 55568 | G6: 54631 | H6: 52695 | I6: 50724 | J6: 49562 | K6: 50548 | L6: 51231 | M6: 51895 | N6: 53619 | O6: 54819 | P6: 55138 | Q6: 53566 | R6: 52947 | S6: 54.22 | T6: 54873 | U6: 54916
A7: Czechia | B7: Employment to population ratio, 15+, total (%) (national estimate) | C7: Percentage | D7: 55647 | E7: 55933 | F7: 54768 | G7: 54188 | H7: 54351 | I7: 54548 | J7: 55154 | K7: 55687 | L7: 56425 | M7: 57551 | N7: 58478 | O7: 59203 | P7: 59164 | Q7: 58268 | R7: 58153 | S7: 58529 | T7: 58404 | U7: 59031
A8: Italy | B8: Employment to population ratio, 15+, total (%) (national estimate) | C8: Percentage | D8: 45.79 | E8: 45.8 | F8: 44.72 | G8: 44173 | H8: 44118 | I8: 43852 | J8: 42865 | K8: 42836 | L8: 43142 | M8: 43715 | N8: 44228 | O8: 44572 | P8: 44895 | Q8: 43.94 | R8: 43.96 | S8: 45138 | T8: 46068 | U8: 46599
A9: Hungary | B9: Employment to population ratio, 15+, total (%) (national estimate) | C9: Percentage | D9: 46597 | E9: 46007 | F9: 44855 | G9: 44719 | H9: 45088 | I9: 45976 | J9: 46.87 | K9: 49534 | L9: 51026 | M9: 52847 | N9: 53935 | O9: 54888 | P9: 55414 | Q9: 54727 | R9: 57341 | S9: 58295 | T9: 58.72 | U9: 58833
A10: Spain | B10: Employment to population ratio, 15+, total (%) (national estimate) | C10: Percentage | D10: 53755 | E10: 52.69 | F10: 48879 | G10: 47785 | H10: 46.91 | I10: 44925 | J10: 43883 | K10: 44.55 | L10: 45853 | M10: 47032 | N10: 48107 | O10: 49088 | P10: 49751 | Q10: 47.91 | R10: 49.05 | S10: 50252 | T10: 50992 | U10: 51438
A11: Austria | B11: Employment to population ratio, 15+, total (%) (national estimate) | C11: Percentage | D11: 56893 | E11: 57558 | F11: 57107 | G11: 57343 | H11: 57558 | I11: 57.67 | J11: 57538 | K11: 57.16 | L11: 57115 | M11: 57427 | N11: 57703 | O11: 58298 | P11: 58514 | Q11: 57651 | R11: 57202 | S11: 58441 | T11: 58364 | U11: 58314
A12: Slovenia | B12: Employment to population ratio, 15+, total (%) (national estimate) | C12: Percentage | D12: 56818 | E12: 56888 | F12: 55.95 | G12: 54889 | H12: 53193 | I12: 52449 | J12: 51461 | K12: 52096 | L12: 52179 | M12: 52068 | N12: 54.59 | O12: 55805 | P12: 55485 | Q12: 54891 | R12: 55704 | S12: 56579 | T12: 56387 | U12: 56563
... A28: Croatia | B28: Employment to population ratio, 15+, total (%) (national estimate) | C28: Percentage | D28: 47684 | E28: 48587 | F28: 48228 | G28: 46474 | H28: 44747 | I28: 43394 | J28: 42304 | K28: 43462 | L28: 44.33 | M28: 44695 | N28: 45811 | O28: 46781 | P28: 47618 | Q28: 47293 | R28: 48306 | S28: 49224 | T28: 49505 | U28: 51178

Sheet EMPLOYrate
A1: REF_AREA_LABEL | B1: INDICATOR_LABEL | C1: UNIT_MEASURE_LABEL | D1: 2007 | E1: 2008 | F1: 2009 | G1: 2010 | H1: 2011 | I1: 2012 | J1: 2013 | K1: 2014 | L1: 2015 | M1: 2016 | N1: 2017 | O1: 2018 | P1: 2019 | Q1: 2020 | R1: 2021 | S1: 2022 | T1: 2023 | U1: 2024
A2: Malta | B2: Employment to population ratio, 15+, total (%) (national estimate) | C2: Percentage | D2: 46.626 | E2: 47.054 | F2: 49.957 | G2: 50.557 | H2: 51.631 | I2: 53.068 | J2: 54.781 | K2: 56.222 | L2: 56.972 | M2: 58.437 | N2: 59.99 | O2: 61.831 | P2: 62.883 | Q2: 63.551 | R2: 65.584 | S2: 68.072 | T2: 69.265 | U2: 65.006
A3: Ireland | B3: Employment to population ratio, 15+, total (%) (national estimate) | C3: Percentage | D3: 63.307 | E3: 61.472 | F3: 56.006 | G3: 53.502 | H3: 52.449 | I3: 52.114 | J3: 53.453 | K3: 54.431 | L3: 55.691 | M3: 56.971 | N3: 57.818 | O3: 58.594 | P3: 59.253 | Q3: 57.684 | R3: 59.629 | S3: 61.792 | T3: 63.699 | U3: 62.992
A4: Cyprus | B4: Employment to population ratio, 15+, total (%) (national estimate) | C4: Percentage | D4: 61.863 | E4: 61.86 | F4: 60.308 | G4: 60.246 | H4: 58.729 | I4: 55.946 | J4: 53.252 | K4: 53.493 | L4: 53.004 | M4: 53.327 | N4: 54.822 | O4: 57.174 | P4: 58.507 | Q4: 57.935 | R4: 59.035 | S4: 60.678 | T4: 61.716 | U4: 61.921
A5: Estonia | B5: Employment to population ratio, 15+, total (%) (national estimate) | C5: Percentage | D5: 57.773 | E5: 57.773 | F5: 52.493 | G5: 50.392 | H5: 53.747 | I5: 55.167 | J5: 56.033 | K5: 56.627 | L5: 58.139 | M5: 58.653 | N5: 59.889 | O5: 60.397 | P5: 60.706 | Q5: 59.098 | R5: 59.753 | S5: 61.987 | T5: 62.219 | U5: 61.953
A6: Portugal | B6: Employment to population ratio, 15+, total (%) (national estimate) | C6: Percentage | D6: 57.25 | E6: 57.344 | F6: 55.568 | G6: 54.631 | H6: 52.695 | I6: 50.724 | J6: 49.562 | K6: 50.548 | L6: 51.231 | M6: 51.895 | N6: 53.619 | O6: 54.819 | P6: 55.138 | Q6: 53.566 | R6: 52.947 | S6: 54.22 | T6: 54.873 | U6: 54.916
A7: Czechia | B7: Employment to population ratio, 15+, total (%) (national estimate) | C7: Percentage | D7: 55.647 | E7: 55.933 | F7: 54.768 | G7: 54.188 | H7: 54.351 | I7: 54.548 | J7: 55.154 | K7: 55.687 | L7: 56.425 | M7: 57.551 | N7: 58.478 | O7: 59.203 | P7: 59.164 | Q7: 58.268 | R7: 58.153 | S7: 58.529 | T7: 58.404 | U7: 59.031
A8: Italy | B8: Employment to population ratio, 15+, total (%) (national estimate) | C8: Percentage | D8: 45.79 | E8: 45.8 | F8: 44.72 | G8: 44.173 | H8: 44.118 | I8: 43.852 | J8: 42.865 | K8: 42.836 | L8: 43.142 | M8: 43.715 | N8: 44.228 | O8: 44.572 | P8: 44.895 | Q8: 43.94 | R8: 43.96 | S8: 45.138 | T8: 46.068 | U8: 46.599
A9: Hungary | B9: Employment to population ratio, 15+, total (%) (national estimate) | C9: Percentage | D9: 46.597 | E9: 46.007 | F9: 44.855 | G9: 44.719 | H9: 45.088 | I9: 45.976 | J9: 46.87 | K9: 49.534 | L9: 51.026 | M9: 52.847 | N9: 53.935 | O9: 54.888 | P9: 55.414 | Q9: 54.727 | R9: 57.341 | S9: 58.295 | T9: 58.72 | U9: 58.833
A10: Spain | B10: Employment to population ratio, 15+, total (%) (national estimate) | C10: Percentage | D10: 53.755 | E10: 52.69 | F10: 48.879 | G10: 47.785 | H10: 46.91 | I10: 44.925 | J10: 43.883 | K10: 44.55 | L10: 45.853 | M10: 47.032 | N10: 48.107 | O10: 49.088 | P10: 49.751 | Q10: 47.91 | R10: 49.05 | S10: 50.252 | T10: 50.992 | U10: 51.438
A11: Austria | B11: Employment to population ratio, 15+, total (%) (national estimate) | C11: Percentage | D11: 56.893 | E11: 57.558 | F11: 57.107 | G11: 57.343 | H11: 57.558 | I11: 57.67 | J11: 57.538 | K11: 57.16 | L11: 57.115 | M11: 57.427 | N11: 57.703 | O11: 58.298 | P11: 58.514 | Q11: 57.651 | R11: 57.202 | S11: 58.441 | T11: 58.364 | U11: 58.314
A12: Slovenia | B12: Employment to population ratio, 15+, total (%) (national estimate) | C12: Percentage | D12: 56.818 | E12: 56.888 | F12: 55.95 | G12: 54.889 | H12: 53.193 | I12: 52.449 | J12: 51.461 | K12: 52.096 | L12: 52.179 | M12: 52.068 | N12: 54.59 | O12: 55.805 | P12: 55.485 | Q12: 54.891 | R12: 55.704 | S12: 56.579 | T12: 56.387 | U12: 56.563
... A28: Croatia | B28: Employment to population ratio, 15+, total (%) (national estimate) | C28: Percentage | D28: 47.684 | E28: 48.587 | F28: 48.228 | G28: 46.474 | H28: 44.747 | I28: 43.394 | J28: 42.304 | K28: 43.462 | L28: 44.33 | M28: 44.695 | N28: 45.811 | O28: 46.781 | P28: 47.618 | Q28: 47.293 | R28: 48.306 | S28: 49.224 | T28: 49.505 | U28: 51.178

Sheet fixedbroadband
A1: tara | D1: 2007 | E1: 2008 | F1: 2009 | G1: 2010 | H1: 2011 | I1: 2012 | J1: 2013 | K1: 2014 | L1: 2015 | M1: 2016 | N1: 2017 | O1: 2018 | P1: 2019 | Q1: 2020 | R1: 2021 | S1: 2022
A2: France | B2: Fixed broadband subscriptions (per 100 people) | C2: Per 100 persons | D2: 25.2273 | E2: 28.4007 | F2: 31.458 | G2: 33.6454 | H2: 35.6938 | I2: 37.4346 | J2: 38.7341 | K2: 40.1422 | L2: 41.3871 | M2: 42.5278 | N2: 43.6243 | O2: 44.4142 | P2: 45.2765 | Q2: 46.4712 | R2: 47.6442 | S2: 48.2502
A3: Slovenia | B3: Fixed broadband subscriptions (per 100 people) | C3: Per 100 persons | D3: 17.1127 | E3: 21.0013 | F3: 22.0588 | G3: 23.013 | H3: 24.1298 | I3: 24.8055 | J3: 25.5111 | K3: 27.0023 | L3: 27.6233 | M3: 28.5889 | N3: 29.1804 | O3: 29.6086 | P3: 30.1395 | Q3: 30.993 | R3: 31.5503 | S3: 32.0105
A4: Ireland | B4: Fixed broadband subscriptions (per 100 people) | C4: Per 100 persons | D4: 17.2691 | E4: 19.8672 | F4: 21.5358 | G4: 22.3721 | H4: 23.3814 | I4: 24.175 | J4: 25.7144 | K4: 27.0222 | L4: 27.8463 | M4: 28.6148 | N4: 29.0795 | O4: 29.3513 | P4: 29.6453 | Q4: 30.4353 | R4: 31.3616 | S4: 31.5363
A5: Croatia | B5: Fixed broadband subscriptions (per 100 people) | C5: Per 100 persons | D5: 8.96789 | E5: 12.2372 | F5: 16.6419 | G5: 19.48 | H5: 20.8566 | I5: 21.5819 | J5: 22.5043 | K5: 23.3319 | L5: 23.5726 | M5: 25.2341 | N5: 26.8651 | O5: 28.0156 | P5: 28.9683 | Q5: 26.0745 | R5: 26.7158 | S5: 27.6607
A6: Sweden | B6: Fixed broadband subscriptions (per 100 people) | C6: Per 100 persons | D6: 30.3915 | E6: 31.4844 | F6: 31.672 | G6: 31.984 | H6: 32.0391 | I6: 32.283 | J6: 32.7855 | K6: 33.8414 | L6: 35.6778 | M6: 37.0822 | N6: 38.3266 | O6: 38.7413 | P6: 39.2906 | Q6: 40.368 | R6: 40.8351 | S6: 40.6093
A7: Lithuania | B7: Fixed broadband subscriptions (per 100 people) | C7: Per 100 persons | D7: 17.3003 | E7: 18.4495 | F7: 20.0357 | G7: 21.9297 | H7: 24.0272 | I7: 25.7288 | J7: 28.2657 | K7: 27.3378 | L7: 28.6774 | M7: 29.8964 | N7: 28.2319 | O7: 28.1445 | P7: 28.2792 | Q7: 28.4989 | R7: 28.7127 | S7: 28.44
A8: Netherlands | B8: Fixed broadband subscriptions (per 100 people) | C8: Per 100 persons | D8: 33.3124 | E8: 34.9757 | F8: 36.7355 | G8: 37.7372 | H8: 38.5614 | I8: 39.3374 | J8: 40.0305 | K8: 40.2288 | L8: 41.088 | M8: 41.9814 | N8: 42.0989 | O8: 42.5152 | P8: 42.5293 | Q8: 42.6667 | R8: 42.9461 | S8: 43.5643
A9: Finland | B9: Fixed broadband subscriptions (per 100 people) | C9: Per 100 persons | D9: 30.5746 | E9: 30.4514 | F9: 29.3246 | G9: 29.0751 | H9: 29.8056 | I9: 30.4324 | J9: 31.6268 | K9: 32.197 | L9: 31.5691 | M9: 31.1529 | N9: 31.0435 | O9: 31.4917 | P9: 32.544 | Q9: 33.3839 | R9: 33.6397 | S9: 34.2952
A10: Czechia | B10: Fixed broadband subscriptions (per 100 people) | C10: Per 100 persons | D10: 14.4785 | E10: 16.9545 | F10: 19.5386 | G10: 21.6091 | H10: 23.9064 | I10: 25.2869 | J10: 27.1727 | K10: 28.4754 | L10: 27.998 | M10: 29.1491 | N10: 29.8453 | O10: 30.5513 | P10: 35.4302 | Q10: 36.4491 | R10: 37.4985 | S10: 37.7137
A11: Romania | B11: Fixed broadband subscriptions (per 100 people) | C11: Per 100 persons | D11: 9.35378 | E11: 12.1504 | F11: 13.6687 | G11: 14.6854 | H11: 16.1875 | I11: 17.5675 | J11: 18.8919 | K11: 20.114 | L11: 21.449 | M11: 22.4983 | N11: 24.1489 | O11: 25.9702 | P11: 27.0606 | Q11: 29.3141 | R11: 31.695 | S11: 33.2116
A12: Luxembourg | B12: Fixed broadband subscriptions (per 100 people) | C12: Per 100 persons | D12: 26.7933 | E12: 29.2849 | F12: 31.3376 | G12: 33.1818 | H12: 32.7339 | I12: 31.9618 | J12: 32.4834 | K12: 33.5803 | L12: 34.2911 | M12: 34.8068 | N12: 35.9768 | O12: 36.8853 | P12: 37.3611 | Q12: 37.2961 | R12: 38.04 | S12: 38.327
A13: Austria | B13: Fixed broadband subscriptions (per 100 people) | C13: Per 100 persons | D13: 19.5493 | E13: 20.7731 | F13: 22.5106 | G13: 24.5114 | H13: 24.9926 | I13: 25.2645 | J13: 26.3223 | K13: 27.5977 | L13: 28.4069 | M13: 28.8776 | N13: 28.5426 | O13: 28.515 | P13: 28.3632 | Q13: 29.2106 | R13: 29.2537 | S13: 29.2343
... A28: Slovak Republic | B28: Fixed broadband subscriptions (per 100 people) | C28: Per 100 persons | D28: 10.1667 | E28: 11.2414 | F28: 14.3927 | G28: 16.2644 | H28: 17.6561 | I28: 19.3435 | J28: 20.4986 | K28: 21.9975 | L28: 23.5009 | M28: 24.6264 | N28: 25.8591 | O28: 27.6954 | P28: 29.1811 | Q28: 31.1925 | R28: 32.6061 | S28: 33.9988

Sheet gdpannual
A1: tara | B1: INDICATOR_LABEL | C1: UNIT_MEASURE_LABEL | D1: 2007 | E1: 2008 | F1: 2009 | G1: 2010 | H1: 2011 | I1: 2012 | J1: 2013 | K1: 2014 | L1: 2015 | M1: 2016 | N1: 2017 | O1: 2018 | P1: 2019 | Q1: 2020 | R1: 2021 | S1: 2022
A2: Ireland | B2: GDP growth (annual %) | C2: Percentage change per annum | D2: 5.3101183 | E2: -4.4840708 | F2: -5.0957828 | G2: 1.6829718 | H2: 1.6088665 | I2: -0.40502942 | J2: 2.1929376 | K2: 9.3857934 | L2: 24.623986 | M2: 1.2227166 | N2: 10.108858 | O2: 7.6886594 | P2: 4.97288 | Q2: 7.1536951 | R2: 16.258188 | S2: 7.5111389
A3: Czechia | B3: GDP growth (annual %) | C3: Percentage change per annum | D3: 5.488826 | E3: 2.6122681 | F3: -4.7983242 | G3: 2.7146651 | H3: 1.7723809 | I3: -0.77066819 | J3: -0.041812416 | K3: 2.2452122 | L3: 4.9587585 | M3: 2.5808701 | N3: 5.1735653 | O3: 2.8303059 | P3: 3.5657766 | Q3: -5.3048796 | R3: 4.0290183 | S3: 2.8471707
A4: Greece | B4: GDP growth (annual %) | C4: Percentage change per annum | D4: 3.5068698 | E4: 0.057474024 | F4: -4.1192761 | G4: -5.6937412 | H4: -9.8767788 | I4: -8.3311342 | J4: -2.272117 | K4: 0.79222506 | L4: -0.22830189 | M4: -0.031794768 | N4: 1.4731247 | O4: 2.0646721 | P4: 2.2771807 | Q4: -9.1962315 | R4: 8.6544979 | S4: 5.5219858
A5: Bulgaria | B5: GDP growth (annual %) | C5: Percentage change per annum | D5: 6.6543879 | E5: 6.1295584 | F5: -3.3471415 | G5: 1.5553598 | H5: 2.0901751 | I5: 0.74881541 | J5: -0.54275139 | K5: 0.94944909 | L5: 3.3975534 | M5: 3.0266284 | N5: 2.7459268 | O5: 2.3301521 | P5: 3.7933177 | Q5: -3.133233 | R5: 7.8281723 | S5: 4.0838641
A6: Hungary | B6: GDP growth (annual %) | C6: Percentage change per annum | D6: 0.33235434 | E6: 0.99343709 | F6: -6.7401661 | G6: 1.0679507 | H6: 1.9167092 | I6: -1.3394845 | J6: 2.0321699 | K6: 4.3343536 | L6: 3.6598162 | M6: 2.4386414 | N6: 4.1241839 | O6: 5.6061381 | P6: 5.077185 | Q6: -4.3387254 | R6: 7.2229158 | S6: 4.1523806
A7: Austria | B7: GDP growth (annual %) | C7: Percentage change per annum | D7: 3.7752247 | E7: 1.4533056 | F7: -3.5862647 | G7: 1.8089824 | H7: 2.927468 | I7: 0.62824624 | J7: -0.25072642 | K7: 0.75579885 | L7: 1.3035233 | M7: 2.1172196 | N7: 2.2722499 | O7: 2.4842211 | P7: 1.7549762 | Q7: -6.3182551 | R7: 4.9230917 | S7: 5.3309638
A8: Cyprus | B8: GDP growth (annual %) | C8: Percentage change per annum | D8: 5.0982261 | E8: 3.6469892 | F8: -2.015082 | G8: 2.282671 | H8: 0.41671187 | I8: -3.4473815 | J8: -6.5874775 | K8: -1.7760587 | L8: 3.4189204 | M8: 6.5735908 | N8: 5.7508324 | O8: 6.2716636 | P8: 5.8755958 | Q8: -3.2206302 | R8: 11.397559 | S8: 8.273726
A9: Spain | B9: GDP growth (annual %) | C9: Percentage change per annum | D9: 3.5335001 | E9: 0.76716575 | F9: -3.7681331 | G9: 0.094122312 | H9: -0.63992064 | I9: -2.8651137 | J9: -1.4273222 | K9: 1.5204859 | L9: 4.0608667 | M9: 2.915156 | N9: 2.8960421 | O9: 2.3954112 | P9: 1.9611785 | Q9: -10.940071 | R9: 6.6831442 | S9: 6.3703171
A10: France | B10: GDP growth (annual %) | C10: Percentage change per annum | D10: 2.5304819 | E10: 0.38017144 | F10: -2.8245515 | G10: 2.0003248 | H10: 2.4375765 | I10: 0.18383526 | J10: 0.78175645 | K10: 0.99783295 | L10: 1.0667547 | M10: 0.86003108 | N10: 2.0836149 | O10: 1.6459087 | P10: 2.0274465 | Q10: -7.4406459 | R10: 6.8823378 | S10: 2.7167626
A11: Germany | B11: GDP growth (annual %) | C11: Percentage change per annum | D11: 2.8891174 | E11: 0.88790233 | F11: -5.5445545 | G11: 4.1346378 | H11: 3.7579688 | I11: 0.46351204 | J11: 0.39699558 | K11: 2.180186 | L11: 1.663006 | M11: 2.2222222 | N11: 2.7979067 | O11: 1.135696 | P11: 0.9777347 | Q11: -4.1319144 | R11: 3.9099999 | S11: 1.8092581
A12: Malta | B12: GDP growth (annual %) | C12: Percentage change per annum | D12: 5.0364017 | E12: 4.4105966 | F12: -1.3952497 | G12: 6.1973504 | H12: 0.99220191 | I12: 4.1016739 | J12: 6.2923338 | K12: 7.6313636 | L12: 9.6207032 | M12: 4.0780036 | N12: 12.971342 | O12: 7.1892148 | P12: 4.0850558 | Q12: -3.4572828 | R12: 13.411704 | S12: 2.4830999
... A28: Finland | B28: GDP growth (annual %) | C28: Percentage change per annum | D28: 5.3128018 | E28: 0.78443124 | F28: -8.0760312 | G28: 3.1682879 | H28: 2.3903946 | I28: -1.5228401 | J28: -0.97974102 | K28: -0.47806842 | L28: 0.46650377 | M28: 2.5719341 | N28: 3.30337 | O28: 1.1929776 | P28: 1.3497385 | Q28: -2.4910361 | R28: 2.6763464 | S28: 0.76304191

Sheet gdppercapita
A1: tara | D1: 2007 | E1: 2008 | F1: 2009 | G1: 2010 | H1: 2011 | I1: 2012 | J1: 2013 | K1: 2014 | L1: 2015 | M1: 2016 | N1: 2017 | O1: 2018 | P1: 2019 | Q1: 2020 | R1: 2021 | S1: 2022
A2: Austria | B2: GDP per capita (current US$) | C2: US dollars | D2: 46622.962 | E2: 51581.398 | F2: 47857.445 | G2: 46611.139 | H2: 51116.895 | I2: 48250.406 | J2: 50305.355 | K2: 51314.972 | L2: 43915.228 | M2: 45061.499 | N2: 47163.743 | O2: 51194.075 | P2: 49885.995 | Q2: 48716.41 | R2: 53648.644 | S2: 52336.773
A3: Belgium | B3: GDP per capita (current US$) | C3: US dollars | D3: 44319.165 | E3: 48303.398 | F3: 44923.34 | G3: 44197.394 | H3: 47760.83 | I3: 44874.171 | J3: 46964.595 | K3: 47995.779 | L3: 40893.805 | M3: 41854.55 | N3: 44035.324 | O3: 47487.21 | P3: 46716.623 | Q3: 45906.288 | R3: 51658.238 | S3: 50605.75
A4: Bulgaria | B4: GDP per capita (current US$) | C4: US dollars | D4: 5888.5708 | E4: 7271.3034 | F4: 6988.2732 | G4: 6853.9481 | H4: 7849.5806 | I4: 7431.9579 | J4: 7795.9809 | K4: 8069.6001 | L4: 7268.6545 | M4: 7822.4992 | N4: 8696.6893 | O4: 9849.384 | P4: 10353.72 | Q4: 10760.212 | R4: 12966.146 | S4: 13999.195
A5: Cyprus | B5: GDP per capita (current US$) | C5: US dollars | D5: 31244.879 | E5: 35397.297 | F5: 32236.449 | G5: 31105.027 | H5: 32485.799 | I5: 28991.936 | J5: 27764.73 | K5: 26993.104 | L5: 23088.441 | M5: 24280.057 | N5: 26247.449 | O5: 29120.375 | P5: 29227.174 | Q5: 28130.342 | R5: 32937.84 | S5: 33231.043
A6: Croatia | B6: GDP per capita (current US$) | C6: US dollars | D6: 13755.832 | E6: 15888.061 | F6: 14474.652 | G6: 13729.765 | H6: 14691.558 | I6: 13507.781 | J6: 14134.947 | K6: 14186.73 | L6: 12283.784 | M6: 12820.165 | N6: 13901.788 | O6: 15460.367 | P6: 15563.599 | Q6: 14807.561 | R6: 17788.787 | S6: 18465.541
A7: Denmark | B7: GDP per capita (current US$) | C7: US dollars | D7: 58631.657 | E7: 64616.666 | F7: 58412.747 | G7: 58104.545 | H7: 61809.738 | I7: 58443.775 | J7: 61377.594 | K7: 62520.451 | L7: 53094.013 | M7: 54500.926 | N7: 57521.551 | O7: 61324.767 | P7: 59404.266 | Q7: 60985.489 | R7: 69340.733 | S7: 67781.094
A8: Estonia | B8: GDP per capita (current US$) | C8: US dollars | D8: 16745.431 | E8: 18205.906 | F8: 14712.449 | G8: 14663.704 | H8: 17555.546 | I8: 17568.214 | J8: 19310.387 | K8: 20581.79 | L8: 17722.156 | M8: 18666.374 | N8: 20851.522 | O8: 23618.136 | P8: 24021.25 | Q8: 23933.994 | R8: 27951.166 | S8: 28340.383
A9: Finland | B9: GDP per capita (current US$) | C9: US dollars | D9: 48473.024 | E9: 53769.473 | F9: 47478.35 | G9: 46506.292 | H9: 51060.324 | I9: 47551.674 | J9: 49691.015 | K9: 50073.776 | L9: 42560.346 | M9: 43451.256 | N9: 46085.017 | O9: 49654.25 | P9: 48358.181 | Q9: 48828.685 | R9: 53099.135 | S9: 50440.56
A10: France | B10: GDP per capita (current US$) | C10: US dollars | D10: 41486.191 | E10: 45464.818 | F10: 41728.088 | G10: 40694.821 | H10: 43929.784 | I10: 40863.581 | J10: 42669.18 | K10: 43148.046 | L10: 36702.432 | M10: 37024.216 | N10: 38687.163 | O10: 41418.177 | P10: 40408.285 | Q10: 39169.861 | R10: 43725.1 | S10: 40988.64
A11: Germany | B11: GDP per capita (current US$) | C11: US dollars | D11: 42350.922 | E11: 46379.165 | F11: 42471.887 | G11: 42396.967 | H11: 47630.976 | I11: 44718.016 | J11: 47206.835 | K11: 48959.599 | L11: 41929.755 | M11: 42948.938 | N11: 45553.934 | O11: 48916.169 | P11: 47656.2 | Q11: 47394.873 | R11: 52349.246 | S11: 50506.518
A12: Greece | B12: GDP per capita (current US$) | C12: US dollars | D12: 28440.763 | E12: 31695.833 | F12: 29425.457 | G12: 26653.049 | H12: 25504.787 | I12: 21624.346 | J12: 21573.345 | K12: 21474.726 | L12: 17980.73 | M12: 17919.243 | N12: 18631.993 | O12: 19873.402 | P12: 19335.36 | Q12: 17886.733 | R12: 20654.7 | S12: 20886.524
A13: Hungary | B13: GDP per capita (current US$) | C13: US dollars | D13: 13934.605 | E13: 15762.632 | F13: 13051.183 | G13: 13189.843 | H13: 14211.461 | I13: 12950.159 | J13: 13739.462 | K13: 14352.502 | L13: 12782.941 | M13: 13215.861 | N13: 14736.167 | O13: 16605.057 | P13: 17012.86 | Q13: 16386.931 | R13: 19030.628 | S13: 18428.029
... A28: Spain | B28: GDP per capita (current US$) | C28: US dollars | D28: 32652.016 | E28: 35603.248 | F28: 32279.821 | G28: 30658.742 | H28: 31824.622 | I28: 28456.444 | J28: 29228.847 | K28: 29707.766 | L28: 25982.442 | M28: 26755.606 | N28: 28381.343 | O28: 30602.421 | P28: 29786.525 | Q28: 27233.943 | R28: 30799.478 | S28: 30319.499

Sheet hightechmanu
A1: tara | C1: 2007 | D1: 2008 | E1: 2009 | F1: 2010 | G1: 2011 | H1: 2012 | I1: 2013 | J1: 2014 | K1: 2015 | L1: 2016 | M1: 2017 | N1: 2018 | O1: 2019 | P1: 2020 | Q1: 2021 | R1: 2022
A2: Austria | B2: Percentage | C2: 12.984024 | D2: 12.661119 | E2: 13.437916 | F2: 13.705374 | G2: 13.255424 | H2: 14.544679 | I2: 15.369065 | J2: 15.490449 | K2: 15.032732 | L2: 14.453259 | M2: 12.8852 | N2: 11.650076 | O2: 11.482535 | P2: 12.271896 | Q2: 11.017122 | R2: 14.91417
A3: Belgium | B3: Percentage | C3: 8.4658386 | D3: 8.9469498 | E3: 11.357545 | F3: 9.2652301 | G3: 8.6748384 | H3: 8.9420008 | I3: 10.640612 | J3: 11.939352 | K3: 12.335174 | L3: 13.331245 | M3: 11.49179 | N3: 11.705864 | O3: 14.144014 | P3: 15.261862 | Q3: 21.379964 | R3: 22.817914
A4: Bulgaria | B4: Percentage | C4: 6.2935056 | D4: 6.9730376 | E4: 8.6660333 | F4: 8.4042516 | G4: 7.8156879 | H4: 8.0475539 | I4: 8.2944022 | J4: 7.5780009 | K4: 8.4502667 | L4: 8.9861031 | M4: 9.6360885 | N4: 10.37289 | O4: 10.85231 | P4: 11.303273 | Q4: 10.924474 | R4: 10.382678
A5: Cyprus | B5: Percentage | C5: 31.295656 | D5: 32.017237 | E5: 32.529426 | F5: 38.20152 | G5: 30.358544 | H5: 16.591497 | I5: 13.083398 | J5: 14.528263 | K5: 12.710824 | L5: 13.328515 | M5: 13.349961 | N5: 19.856794 | O5: 19.874216 | P5: 12.244828 | Q5: 15.969003 | R5: 17.659598
A6: Czechia | B6: Percentage | C6: 15.286166 | D6: 15.789935 | E6: 17.443541 | F6: 17.876107 | G6: 18.715353 | H6: 18.589206 | I6: 17.334369 | J6: 17.371232 | K6: 17.734407 | L6: 16.872802 | M6: 17.829257 | N6: 19.554998 | O6: 20.710413 | P6: 22.582515 | Q6: 20.356091 | R6: 21.835362
A7: Germany | B7: Percentage | C7: 15.462393 | D7: 15.076242 | E7: 16.794291 | F7: 16.889686 | G7: 16.341719 | H7: 17.227286 | I7: 17.297991 | J7: 17.209715 | K7: 17.824375 | L7: 18.082701 | M7: 15.850579 | N7: 15.747434 | O7: 16.386931 | P7: 15.503196 | Q7: 15.385105 | R7: 17.372012
A8: Denmark | B8: Percentage | C8: 18.257362 | D8: 16.857034 | E8: 18.931051 | F8: 15.468841 | G8: 15.274565 | H8: 15.826335 | I8: 15.822591 | J8: 15.717961 | K8: 17.1655 | L8: 14.883324 | M8: 12.455721 | N8: 12.35473 | O8: 12.039997 | P8: 13.234393 | Q8: 13.924747 | R8: 17.11913
A9: Spain | B9: Percentage | C9: 5.612971 | D9: 5.5848809 | E9: 6.4732406 | F9: 6.5581983 | G9: 6.586264 | H9: 7.2508066 | I9: 6.970053 | J9: 6.9121536 | K9: 6.8883351 | L9: 7.8024814 | M9: 6.9994901 | N9: 6.7669355 | O9: 6.8464009 | P9: 7.7684214 | Q9: 9.3932038 | R9: 12.583719
A10: Estonia | B10: Percentage | C10: 12.125723 | D10: 11.438008 | E10: 11.385937 | F10: 15.734651 | G10: 22.226828 | H10: 20.567612 | I10: 20.676115 | J10: 23.652439 | K10: 22.714468 | L10: 21.907258 | M10: 17.964694 | N10: 18.204526 | O10: 16.964425 | P10: 20.621626 | Q10: 20.630116 | R10: 18.018644
A11: Finland | B11: Percentage | C11: 21.767756 | D11: 21.48789 | E11: 18.01598 | F11: 13.146864 | G11: 11.075461 | H11: 10.473914 | I11: 9.0264326 | J11: 10.052521 | K11: 10.184283 | L11: 10.05283 | M11: 9.6573147 | N11: 9.0176536 | O11: 9.2147012 | P11: 9.9823003 | Q11: 10.293754 | R11: 9.6239284
A12: France | B12: Percentage | C12: 20.142835 | D12: 21.461798 | E12: 24.123558 | F12: 26.32338 | G12: 25.119359 | H12: 26.690632 | I12: 27.181718 | J12: 27.470274 | K12: 28.211691 | L12: 27.93318 | M12: 26.018022 | N12: 25.934785 | O12: 26.926598 | P12: 23.228836 | Q12: 21.924713 | R12: 22.983183
A13: Greece | B13: Percentage | C13: 9.1144682 | D13: 10.850667 | E13: 12.227178 | F13: 11.595656 | G13: 11.250586 | H13: 10.143585 | I13: 8.4789319 | J13: 11.506031 | K13: 12.921825 | L13: 13.727008 | M13: 12.11489 | N13: 12.955189 | O13: 12.522256 | P13: 13.251867 | Q13: 12.284868 | R13: 14.470865
... A28: Sweden | B28: Percentage | C28: 16.805723 | D28: 17.248587 | E28: 18.773299 | F28: 19.411484 | G28: 18.698162 | H28: 17.983832 | I28: 18.025383 | J28: 17.877467 | K28: 18.129095 | L28: 17.837602 | M28: 15.110342 | N28: 14.164314 | O28: 14.505784 | P28: 15.135951 | Q28: 13.934832 | R28: 17.256654
